---
- name: ðŸš€ðŸš€ðŸš€ Start my workflow twice ðŸš€ðŸš€ðŸš€
  hosts: localhost
  gather_facts: False

  vars_files:
  - vault.yml
  - vars.yml

  collections:
  - ansible.controller

  tasks:
  - name: ðŸš€ Workflow launch where everything works ðŸš€
    ansible.controller.workflow_launch:
      controller_host: "{{ aap2_host }}"
      controller_username: "{{ aap2_username }}"
      controller_password: "{{ aap2_password }}"
      validate_certs: False
      name: "{{ customer }} WORKFLOW"
      extra_vars: {'job1_result': 'succeed'}

  - name: ðŸš€ Workflow launch with remediation ðŸš€
    ansible.controller.workflow_launch:
      controller_host: "{{ aap2_host }}"
      controller_username: "{{ aap2_username }}"
      controller_password: "{{ aap2_password }}"
      validate_certs: False
      name: "{{ customer }} WORKFLOW"
      extra_vars: {'job1_result': 'fail'}