---
- name: ðŸš€ðŸš€ðŸš€ Start my workflow twice ðŸš€ðŸš€ðŸš€
  hosts: localhost
  gather_facts: False

  vars_files:
  - vault.yml
  - vars.yml

  collections:
  - ansible.controller

  tasks:
  - name: ðŸš€ Workflow launch and fail on purpose (and ignore the error) ðŸš€
    ansible.controller.workflow_launch:
      controller_host: "{{ aap2_host }}"
      controller_username: "{{ aap2_username }}"
      controller_password: "{{ aap2_password }}"
      validate_certs: False
      name: "{{ customer }} WORKFLOW"
      extra_vars: {'expected_result': 'fail'}
    ignore_errors: true

  - name: ðŸš€ Workflow launch and succeed ðŸš€
    ansible.controller.workflow_launch:
      controller_host: "{{ aap2_host }}"
      controller_username: "{{ aap2_username }}"
      controller_password: "{{ aap2_password }}"
      validate_certs: False
      name: "{{ customer }} WORKFLOW"
      extra_vars: {'expected_result': 'succeed'}
